2019-06-02 20:58:11,189 INFO: Microblog startup [in /home/pilovec/www/microblog/app/__init__.py:43]
2019-06-02 21:41:53,997 INFO: Microblog startup [in /home/pilovec/www/microblog/app/__init__.py:43]
2019-06-02 21:42:00,151 ERROR: Exception on /index [GET] [in /home/pilovec/.virtualenvs/microblog_env/lib/python3.6/site-packages/flask/app.py:1761]
Traceback (most recent call last):
  File "/home/pilovec/.virtualenvs/microblog_env/lib/python3.6/site-packages/flask/app.py", line 2292, in wsgi_app
    response = self.full_dispatch_request()
  File "/home/pilovec/.virtualenvs/microblog_env/lib/python3.6/site-packages/flask/app.py", line 1815, in full_dispatch_request
    rv = self.handle_user_exception(e)
  File "/home/pilovec/.virtualenvs/microblog_env/lib/python3.6/site-packages/flask/app.py", line 1718, in handle_user_exception
    reraise(exc_type, exc_value, tb)
  File "/home/pilovec/.virtualenvs/microblog_env/lib/python3.6/site-packages/flask/_compat.py", line 35, in reraise
    raise value
  File "/home/pilovec/.virtualenvs/microblog_env/lib/python3.6/site-packages/flask/app.py", line 1813, in full_dispatch_request
    rv = self.dispatch_request()
  File "/home/pilovec/.virtualenvs/microblog_env/lib/python3.6/site-packages/flask/app.py", line 1799, in dispatch_request
    return self.view_functions[rule.endpoint](**req.view_args)
  File "/home/pilovec/.virtualenvs/microblog_env/lib/python3.6/site-packages/flask_login/utils.py", line 261, in decorated_view
    return func(*args, **kwargs)
  File "/home/pilovec/www/microblog/app/routes.py", line 34, in index
    posts=posts)
  File "/home/pilovec/.virtualenvs/microblog_env/lib/python3.6/site-packages/flask/templating.py", line 135, in render_template
    context, ctx.app)
  File "/home/pilovec/.virtualenvs/microblog_env/lib/python3.6/site-packages/flask/templating.py", line 117, in _render
    rv = template.render(context)
  File "/home/pilovec/.virtualenvs/microblog_env/lib/python3.6/site-packages/jinja2/asyncsupport.py", line 76, in render
    return original_render(self, *args, **kwargs)
  File "/home/pilovec/.virtualenvs/microblog_env/lib/python3.6/site-packages/jinja2/environment.py", line 1008, in render
    return self.environment.handle_exception(exc_info, True)
  File "/home/pilovec/.virtualenvs/microblog_env/lib/python3.6/site-packages/jinja2/environment.py", line 780, in handle_exception
    reraise(exc_type, exc_value, tb)
  File "/home/pilovec/.virtualenvs/microblog_env/lib/python3.6/site-packages/jinja2/_compat.py", line 37, in reraise
    raise value.with_traceback(tb)
  File "/home/pilovec/www/microblog/app/templates/index.html", line 1, in top-level template code
    {% extends "base.html" %}
  File "/home/pilovec/www/microblog/app/templates/base.html", line 31, in top-level template code
    {% block content %}{% endblock %}
  File "/home/pilovec/www/microblog/app/templates/index.html", line 18, in block "content"
    {% include '_post.html' %}
  File "/home/pilovec/www/microblog/app/templates/_post.html", line 3, in top-level template code
    <td><img src="{{ post.author.avatar(36) }}"></td>
jinja2.exceptions.UndefinedError: 'dict object' has no attribute 'avatar'
2019-06-02 21:42:03,160 ERROR: Exception on /index [GET] [in /home/pilovec/.virtualenvs/microblog_env/lib/python3.6/site-packages/flask/app.py:1761]
Traceback (most recent call last):
  File "/home/pilovec/.virtualenvs/microblog_env/lib/python3.6/site-packages/flask/app.py", line 2292, in wsgi_app
    response = self.full_dispatch_request()
  File "/home/pilovec/.virtualenvs/microblog_env/lib/python3.6/site-packages/flask/app.py", line 1815, in full_dispatch_request
    rv = self.handle_user_exception(e)
  File "/home/pilovec/.virtualenvs/microblog_env/lib/python3.6/site-packages/flask/app.py", line 1718, in handle_user_exception
    reraise(exc_type, exc_value, tb)
  File "/home/pilovec/.virtualenvs/microblog_env/lib/python3.6/site-packages/flask/_compat.py", line 35, in reraise
    raise value
  File "/home/pilovec/.virtualenvs/microblog_env/lib/python3.6/site-packages/flask/app.py", line 1813, in full_dispatch_request
    rv = self.dispatch_request()
  File "/home/pilovec/.virtualenvs/microblog_env/lib/python3.6/site-packages/flask/app.py", line 1799, in dispatch_request
    return self.view_functions[rule.endpoint](**req.view_args)
  File "/home/pilovec/.virtualenvs/microblog_env/lib/python3.6/site-packages/flask_login/utils.py", line 261, in decorated_view
    return func(*args, **kwargs)
  File "/home/pilovec/www/microblog/app/routes.py", line 34, in index
    posts=posts)
  File "/home/pilovec/.virtualenvs/microblog_env/lib/python3.6/site-packages/flask/templating.py", line 135, in render_template
    context, ctx.app)
  File "/home/pilovec/.virtualenvs/microblog_env/lib/python3.6/site-packages/flask/templating.py", line 117, in _render
    rv = template.render(context)
  File "/home/pilovec/.virtualenvs/microblog_env/lib/python3.6/site-packages/jinja2/asyncsupport.py", line 76, in render
    return original_render(self, *args, **kwargs)
  File "/home/pilovec/.virtualenvs/microblog_env/lib/python3.6/site-packages/jinja2/environment.py", line 1008, in render
    return self.environment.handle_exception(exc_info, True)
  File "/home/pilovec/.virtualenvs/microblog_env/lib/python3.6/site-packages/jinja2/environment.py", line 780, in handle_exception
    reraise(exc_type, exc_value, tb)
  File "/home/pilovec/.virtualenvs/microblog_env/lib/python3.6/site-packages/jinja2/_compat.py", line 37, in reraise
    raise value.with_traceback(tb)
  File "/home/pilovec/www/microblog/app/templates/index.html", line 1, in top-level template code
    {% extends "base.html" %}
  File "/home/pilovec/www/microblog/app/templates/base.html", line 31, in top-level template code
    {% block content %}{% endblock %}
  File "/home/pilovec/www/microblog/app/templates/index.html", line 18, in block "content"
    {% include '_post.html' %}
  File "/home/pilovec/www/microblog/app/templates/_post.html", line 3, in top-level template code
    <td><img src="{{ post.author.avatar(36) }}"></td>
jinja2.exceptions.UndefinedError: 'dict object' has no attribute 'avatar'
2019-06-02 21:42:19,790 ERROR: Exception on /index [GET] [in /home/pilovec/.virtualenvs/microblog_env/lib/python3.6/site-packages/flask/app.py:1761]
Traceback (most recent call last):
  File "/home/pilovec/.virtualenvs/microblog_env/lib/python3.6/site-packages/flask/app.py", line 2292, in wsgi_app
    response = self.full_dispatch_request()
  File "/home/pilovec/.virtualenvs/microblog_env/lib/python3.6/site-packages/flask/app.py", line 1815, in full_dispatch_request
    rv = self.handle_user_exception(e)
  File "/home/pilovec/.virtualenvs/microblog_env/lib/python3.6/site-packages/flask/app.py", line 1718, in handle_user_exception
    reraise(exc_type, exc_value, tb)
  File "/home/pilovec/.virtualenvs/microblog_env/lib/python3.6/site-packages/flask/_compat.py", line 35, in reraise
    raise value
  File "/home/pilovec/.virtualenvs/microblog_env/lib/python3.6/site-packages/flask/app.py", line 1813, in full_dispatch_request
    rv = self.dispatch_request()
  File "/home/pilovec/.virtualenvs/microblog_env/lib/python3.6/site-packages/flask/app.py", line 1799, in dispatch_request
    return self.view_functions[rule.endpoint](**req.view_args)
  File "/home/pilovec/.virtualenvs/microblog_env/lib/python3.6/site-packages/flask_login/utils.py", line 261, in decorated_view
    return func(*args, **kwargs)
  File "/home/pilovec/www/microblog/app/routes.py", line 34, in index
    posts=posts)
  File "/home/pilovec/.virtualenvs/microblog_env/lib/python3.6/site-packages/flask/templating.py", line 135, in render_template
    context, ctx.app)
  File "/home/pilovec/.virtualenvs/microblog_env/lib/python3.6/site-packages/flask/templating.py", line 117, in _render
    rv = template.render(context)
  File "/home/pilovec/.virtualenvs/microblog_env/lib/python3.6/site-packages/jinja2/asyncsupport.py", line 76, in render
    return original_render(self, *args, **kwargs)
  File "/home/pilovec/.virtualenvs/microblog_env/lib/python3.6/site-packages/jinja2/environment.py", line 1008, in render
    return self.environment.handle_exception(exc_info, True)
  File "/home/pilovec/.virtualenvs/microblog_env/lib/python3.6/site-packages/jinja2/environment.py", line 780, in handle_exception
    reraise(exc_type, exc_value, tb)
  File "/home/pilovec/.virtualenvs/microblog_env/lib/python3.6/site-packages/jinja2/_compat.py", line 37, in reraise
    raise value.with_traceback(tb)
  File "/home/pilovec/www/microblog/app/templates/index.html", line 1, in top-level template code
    {% extends "base.html" %}
  File "/home/pilovec/www/microblog/app/templates/base.html", line 31, in top-level template code
    {% block content %}{% endblock %}
  File "/home/pilovec/www/microblog/app/templates/index.html", line 18, in block "content"
    {% include '_post.html' %}
  File "/home/pilovec/www/microblog/app/templates/_post.html", line 3, in top-level template code
    <td><img src="{{ post.author.avatar(36) }}"></td>
jinja2.exceptions.UndefinedError: 'dict object' has no attribute 'avatar'
2019-06-02 21:43:29,824 INFO: Microblog startup [in /home/pilovec/www/microblog/app/__init__.py:43]
2019-06-02 21:47:04,801 INFO: Microblog startup [in /home/pilovec/www/microblog/app/__init__.py:43]
2019-06-02 21:50:49,327 INFO: Microblog startup [in /home/pilovec/www/microblog/app/__init__.py:43]
2019-06-02 22:18:13,383 INFO: Microblog startup [in /home/pilovec/www/microblog/app/__init__.py:43]
2019-06-02 22:19:19,045 INFO: Microblog startup [in /home/pilovec/www/microblog/app/__init__.py:43]
2019-06-05 11:57:52,873 INFO: Microblog startup [in C:\Users\teperchuk-av\www\microblog\home_work\app\__init__.py:43]
2019-06-05 12:11:01,178 INFO: Microblog startup [in C:\Users\teperchuk-av\www\microblog\home_work\app\__init__.py:43]
2019-06-05 12:19:57,292 INFO: Microblog startup [in C:\Users\teperchuk-av\www\microblog\home_work\app\__init__.py:43]
